Workbook

Sheet Combat System Notes (Cam) 
A1: time | B1: red | C1: ATK | D1: atk dmg | E1: more atk less interactions
A2: distance | B2: yellow | C2: DEF | D2: dmg reduction | E2: more def more interactions
B3: green | C3: SPD | D3: distance per tick | E3: more spd less time wasted
B4: blue | C4: STA | D4: time before atk | E4: more sta less time wasted
A7: time as units = time unit
A8: distance as units = m
E13: trigger conditions | H13: how movement? | I13: default move towards opponent
A14: Starting Position, 10m away from each other | D14: atks have: | E14: startup | I14: how fast? based on spd, more spd = more distance per tick
A15: What happens every tick? | E15: endlag
A16: check if can do any attacks | E16: dmg
A17: if can attack, then attack | E17: effects
A18: if cannot attack, then move
D21: trigger conditions (base atk): | E21: distance
A24: if not hit in current tick | B24: move | C24: if strategy is offensive | D24: move forward until right next to opponent | F24: prioritize attacks being in range | I24: close distance, minimal time loss before action
D25: move backwards during opp attack startup
D26: stay put when
C28: if strategy is balanced | D28: move forward until self base atk tip range | F28: prioritize evasion while being able to land attacks | I28: mid distance, balanced time loss before action
D29: move backwards when within self base atk tip range
D30: stay put when
C32: if strategy is defensive | D32: move forwards when action available | F32: prioritize having actions before initiating | I32: far distance, high time loss before action
D33: move backward until action goal is hit
D34: stay put when
A36: if hit in current tick | B36: try attack | C36: if can attack | D36: use attack
C37: if cannot because | D37: out of range | E37: save action for next tick, initiate move instead
D38: in hitstun | E38: save action for next tick
A41: basic attacks come out at set/random intervals
A42: techniques:
A43: - rng activation with condition checks | C43: STA = 5 - rng roll
A44: atks should have range | C44: Action Goal = 50
A45: - has cooldown | C45: Base Tick = 0.1s
C46: Player action = 0
C47: every 0.1s, add 5 to player action
A48: technique priority based on loadout arrangement | C48: once player action hits >= 50, player gets to do an action (specifically for basic attacks or rng techniques?)
A52: Potential mechanics:
A53: stay put and moving back = defend? | C53: solid, lets us capitalize more on defense
A54: move forward = increase action goal rate by spd? | C54: debatable, less likely
A55: if both chars are in range for their basic atks, clash regardless of action goal? | B55: how to determine clash winner for something like this? | C55: i want things to happen more frequently, and random, no answer to this yet | E55: potential answer: both clashers choose from their technique pool
A56: CLASHING
A59: Affinity:
A60: increases chance of proccing techniques
...

Sheet Game flow chart
A1: Battle prototype game process flow | D1: Relevant Stats
A2: Test | D2: Speed | E2: Sta | F2: Attk | G2: Def | H2: Hp
A3: P1 | B3: Tyran Rex | D3: 5m/t | E3: 5 | F3: 5 | G3: 5 | H3: 50
A4: P2 | B4: Sastrei Taurus | D4: 5m/t | E4: 5 | F4: 5 | G4: 5 | H4: 50
A6: Tyran Rex | D6: Spawn distance between char is 100 | F6: Action goal is 50 | G6: attk range 5m
A7: Strategy | B7: Offensive | F7: Attk startup | G7: 1
B8: Offensive char only attk when the distance between both chars is <=3m | F8: Attk active | G8: 1
A9: Sastrei Taurus | F9: Attk recovery | G9: 1
A10: Strategy | B10: Offensive | F10: Attk dmg | G10: 5
B11: Offensive char only attk when the distance between both chars is <= 3m | F11: Hitstun | G11: 3
F12: Blow back | G12: 5m
A15: Game Tick | B15: Action Played | C15: Type of actions | D15: Condition of actions | E15: Notes | F15: 100
A16: 0 | B16: Both player spawns in | C16: System | D16: Universal | E16: always happens at the start of the game
B17: Both roll to determine STA roll | C17: System | D17: Universal | E17: always happens at the start of the game
B18: P1 roll 5 | C18: System | D18: Universal | E18: always happens at the start of the game
B19: P2 roll 4 | C19: System | D19: Universal | E19: always happens at the start of the game
E20: P1 HP 50
E21: P2 HP 50
E22: Distance between both char is 100m | F22: =F15 -> 100
A24: 1 | B24: P1 gain 5 towards action goal | C24: System | D24: Offensive Strategy | E24: ="action goal is " & A24*5 &"/50" -> action goal is 5/50 | F24: =F22 -> 100
B25: P1 Check for P2 distance | C25: Char Checks | D25: Universal | E25: ="Distance between both char is " & F24 & "m" -> Distance between both char is 100m
B26: P1 check action goal to check are they able to attk | C26: Char Checks | D26: Universal | E26: ="action goal is " & A24*5 &"/50, P1 cannot attk" -> action goal is 5/50, P1 cannot attk
B27: P1 checks own attk range relative to P2 | C27: Char Checks | D27: Universal | E27: ="Attk range 5, Distance between both char is " &F24&"m" -> Attk range 5, Distance between both char is 100m
B28: P1 don’t attk | C28: Char Decisions | D28: Offensive Strategy | E28: P1 cannot attk and also attk is not in range
B29: Move Towards P2 5 unit | C29: Char Decisions | D29: Offensive Strategy | E29: P1 move because cannot attk, distance between -5m | F29: -5
B30: P2 gain 4 towards action goal | C30: System | D30: Offensive Strategy | E30: ="action goal is " & A24*4 &"/50" -> action goal is 4/50
B31: P2 Check for P1 distance | C31: Char Checks | D31: Universal | E31: ="Distance between both char is " & F24 & "m" -> Distance between both char is 100m
B32: P2 check action goal to check are they able to attk | C32: Char Checks | D32: Universal | E32: ="action goal is " & A24*4 &"/50, P2 cannot attk" -> action goal is 4/50, P2 cannot attk
B33: P2 checks own attk range relative to P1 | C33: Char Checks | D33: Universal | E33: ="Attk range 5, Distance between both char is " &F24&"m" -> Attk range 5, Distance between both char is 100m
B34: P2 don’t attk | C34: Char Decisions | D34: Offensive Strategy | E34: P2 cannot attk and also attk is not in range
B35: Move Towards P1 5 unit | C35: Char Decisions | D35: Offensive Strategy | E35: P2 move because cannot attk, distance between -5m | F35: -5
E36: P1 HP 50
E37: P2 HP 50
E38: ="Distance between both char is " & F24+F29+F35 &"m" -> Distance between both char is 90m | F38: =F24+F29+F35 -> 90
A40: 2 | B40: P1 gain 5 towards action goal | C40: System | D40: Offensive Strategy | E40: ="action goal is " & A40*5 &"/50" -> action goal is 10/50 | F40: =F38 -> 90
B41: P1 Check for P2 distance | C41: Char Checks | D41: Universal | E41: ="Distance between both char is " & F40 & "m" -> Distance between both char is 90m
B42: P1 check action goal to check are they able to attk | C42: Char Checks | D42: Universal | E42: ="action goal is " & A40*5 &"/50, P1 cannot attk" -> action goal is 10/50, P1 cannot attk
B43: P1 checks own attk range relative to P2 | C43: Char Checks | D43: Universal | E43: ="Attk range 5, Distance between both char is " &F40&"m" -> Attk range 5, Distance between both char is 90m
B44: P1 don’t attk | C44: Char Decisions | D44: Offensive Strategy | E44: P1 cannot attk and also attk is not in range
B45: Move Towards P2 5 unit | C45: Char Decisions | D45: Offensive Strategy | E45: P1 move because cannot attk, distance between -5m | F45: -5
...

Sheet back up
A1: P1 gain 5 towards action goal | B1: System | C1: Offensive Strategy | D1: ="action goal is " & 'Game flow chart'!A40*5 &"/50" -> action goal is 10/50
A2: P1 Check for P2 distance | B2: Char Checks | C2: Universal | D2: Distance between both char is 90m
A3: P1 check action goal to check are they able to attk | B3: Char Checks | C3: Universal | D3: action goal is 10/50, P1 cannot attk
A4: P1 checks own attk range relative to P2 | B4: Char Checks | C4: Universal | D4: Attk range 5, Distance between both char is 90m
A5: P1 don’t attk | B5: Char Decisions | C5: Offensive Strategy | D5: P1 cannot attk and also attk is not in range
A6: Move Towards P2 5 unit | B6: Char Decisions | C6: Offensive Strategy | D6: P1 move because cannot attk, distance between -5m
A7: P2 gain 4 towards action goal | B7: System | C7: Offensive Strategy | D7: ="action goal is " & 'Game flow chart'!A40*4 &"/50" -> action goal is 8/50
A8: P2 Check for P1 distance | B8: Char Checks | C8: Universal | D8: Distance between both char is 90m
A9: P2 check action goal to check are they able to attk | B9: Char Checks | C9: Universal | D9: action goal is 8/50, P2 cannot attk
A10: P2 checks own attk range relative to P1 | B10: Char Checks | C10: Universal | D10: Attk range 5, Distance between both char is 90m
A11: P2 don’t attk | B11: Char Decisions | C11: Offensive Strategy | D11: P2 cannot attk and also attk is not in range
A12: Move Towards P1 5 unit | B12: Char Decisions | C12: Offensive Strategy | D12: P2 move because cannot attk, distance between -5m
D13: P1 HP 50
D14: P2 HP 50
D15: Distance between both char is [90-5-5]=80m
A17: P1 gain 5 towards action goal | B17: System | C17: Offensive Strategy | D17: ="action goal is " & 'Game flow chart'!A56*5 &"/50" -> action goal is 15/50
A18: P1 Check for P2 distance | B18: Char Checks | C18: Universal | D18: Distance between both char is 80m
A19: P1 check action goal to check are they able to attk | B19: Char Checks | C19: Universal | D19: action goal is 10/50, P1 cannot attk
A20: P1 checks own attk range relative to P2 | B20: Char Checks | C20: Universal | D20: Attk range 5, Distance between both char is 80m
A21: P1 don’t attk | B21: Char Decisions | C21: Offensive Strategy | D21: P1 cannot attk and also attk is not in range
A22: Move Towards P2 5 unit | B22: Char Decisions | C22: Offensive Strategy | D22: P1 move because cannot attk, distance between -5m
A23: P2 gain 4 towards action goal | B23: System | C23: Offensive Strategy | D23: ="action goal is " & 'Game flow chart'!A56*4 &"/50" -> action goal is 12/50
A24: P2 Check for P1 distance | B24: Char Checks | C24: Universal | D24: Distance between both char is 80m
A25: P2 check action goal to check are they able to attk | B25: Char Checks | C25: Universal | D25: action goal is 12/50, P2 cannot attk
A26: P2 checks own attk range relative to P1 | B26: Char Checks | C26: Universal | D26: Attk range 5, Distance between both char is 80m
A27: P2 don’t attk | B27: Char Decisions | C27: Offensive Strategy | D27: P2 cannot attk and also attk is not in range
A28: Move Towards P1 5 unit | B28: Char Decisions | C28: Offensive Strategy | D28: P2 move because cannot attk, distance between -5m
D29: P1 HP 50
D30: P2 HP 50
D31: Distance between both char is [80-5-5]=70m
A33: P1 gain 5 towards action goal | B33: System | C33: Offensive Strategy | D33: ="action goal is " & 'Game flow chart'!A72*5 &"/50" -> action goal is 20/50
A34: P1 Check for P2 distance | B34: Char Checks | C34: Universal | D34: Distance between both char is 70m
A35: P1 check action goal to check are they able to attk | B35: Char Checks | C35: Universal | D35: action goal is 20/50, P1 cannot attk
A36: P1 checks own attk range relative to P2 | B36: Char Checks | C36: Universal | D36: Attk range 5, Distance between both char is 70m
A37: P1 don’t attk | B37: Char Decisions | C37: Offensive Strategy | D37: P1 cannot attk and also attk is not in range
A38: Move Towards P2 5 unit | B38: Char Decisions | C38: Offensive Strategy | D38: P1 move because cannot attk, distance between -5m
A39: P2 gain 4 towards action goal | B39: System | C39: Offensive Strategy | D39: ="action goal is " & 'Game flow chart'!A72*4 &"/50" -> action goal is 16/50
A40: P2 Check for P1 distance | B40: Char Checks | C40: Universal | D40: Distance between both char is 70m
A41: P2 check action goal to check are they able to attk | B41: Char Checks | C41: Universal | D41: action goal is 16/50, P2 cannot attk
A42: P2 checks own attk range relative to P1 | B42: Char Checks | C42: Universal | D42: Attk range 5, Distance between both char is 70m
...

Sheet Player actions on BG analysis
A1: Player Actions (Board): | B1: What does it do | H1: char attributes | I1: what they do
A2: roll dice | B2: determines available landing spots | H2: pmagic | I2: hp
A3: choose landing spot | B3: diff landing spots = diff effects | H3: affinity | I3: unlock inconsistent effects and new paths to greater power
A4: camp -> train | B4: learn new techniques, - pmagic | H4: technique list
A5: camp -> forage | B5: - pmagic, get ingredients and maybe techniques
A6: camp -> cook | B6: use ingredients to get benefits
A7: camp -> barter | B7: trade useless ingredients to get what you need next turn
A8: crossroads event - rival meet -> interact | B8: something good or bad could happen between you and the rival, good example: get technique, bad example: ??? | F8: crossroad events trigger by chance or by landing on a crossroad
A9: crossroads event - rival meet -> challenge | B9: battle, win -> get techniques, lose -> KO but not game over
A10: crossroads event - rival meet -> leave | B10: lets you avoid bad situations

Sheet Sheet2
A1: Offensive | B1: Offensive | C1: (action goal diff)
A2: Nuetral
A3: run towards each other
A4: they reach other but both not hit action goal | E4: (one person reach action goal and start attk, both hit action goal)
A5: one reach action goal before hitting distance check | F5: (continue running until in range of the strategy)
A7: Advantage and disadvantage
A8: If one hit both dist and AG checks, they attk first | F8: opponent see startup they move back (intention to block when attk will land)
A9: attk active | F9: if attk lands, opponent will block
A10: attk recovery | F10: oppenent in block stun
A12: If clash | F12: both attk active frame hitbox hit each other
A17: clash formula
A18: (P2atk stat+ P2 def stat)/(P1atk stat+P1def stat)+(P2atk stat+ P2 def stat)x100=P2 percentage of winning clash (weight when coin toss)
A20: if win clash, opponent knocked back and gets stun until they get hit again

Sheet Dino Exp MU
B1: trex O | C1: trex B | D1: trex D | E1: Carno O | F1: Carno B | G1: Carno D | H1: Fukui O | I1: Fukui B | J1: Fukui D | K1: Armaga O | L1: Armaga B | M1: Armaga D
A2: trex O | B2: 5-5 | C2: 6-4 | D2: 7-3 | E2: 7-3 | F2: 6-4 | G2: 5-5 | H2: 7-3 | I2: 5-5 | J2: 3-7 | K2: 8-2 | L2: 6-4 | M2: 5-5
A3: trex B | B3: 4-6 | C3: 5-5 | D3: 6-4 | E3: 6-4 | F3: 3-7 | G3: 4-6 | H3: 6-4 | I3: 4-6 | J3: 2-8 | K3: 6-4 | L3: 4-6 | M3: 3-7
A4: trex D | B4: 3-7 | C4: 4-6 | D4: 5-5 | E4: 4-6 | F4: 2-8 | G4: 5-5 | H4: 4-6 | I4: 3-7 | J4: 1-9 | K4: 5-5 | L4: 4-6 | M4: 2-8
A5: Carno O | B5: 3-7 | C5: 4-6 | D5: 6-4 | E5: 5-5 | F5: 3-7 | G5: 4-6 | H5: 6-4 | I5: 7-3 | J5: 5-5 | K5: 7-3 | L5: 6-4 | M5: 4-6
A6: Carno B | B6: 4-6 | C6: 7-3 | D6: 8-2 | E6: 7-3 | F6: 5-5 | G6: 6-4 | H6: 7-3 | I6: 6-4 | J6: 4-6 | K6: 7-3 | L6: 5-5 | M6: 4-6
A7: Carno D | B7: 5-5 | C7: 6-4 | D7: 5-5 | E7: 6-4 | F7: 4-6 | G7: 5-5 | H7: 6-4 | I7: 4-6 | J7: 3-7 | K7: 5-5 | L7: 4-6 | M7: 3-7
A8: Fukui O | B8: 3-7 | C8: 5-5 | D8: 7-3 | E8: 4-6 | F8: 3-7 | G8: 4-6 | H8: 5-5 | I8: 4-6 | J8: 3-7 | K8: 5-5 | L8: 4-6 | M8: 6-4
A9: Fukui B | B9: 5-5 | C9: 6-4 | D9: 7-3 | E9: 3-7 | F9: 4-6 | G9: 6-4 | H9: 6-4 | I9: 5-5 | J9: 4-6 | K9: 7-3 | L9: 5-5 | M9: 6-4
A10: Fukui D | B10: 7-3 | C10: 8-2 | D10: 9-1 | E10: 5-5 | F10: 6-4 | G10: 7-3 | H10: 7-3 | I10: 6-4 | J10: 5-5 | K10: 8-2 | L10: 4-6 | M10: 7-3
A11: Armaga O | B11: 8-2 | C11: 6-4 | D11: 5-5 | E11: 5-5 | F11: 3-7 | G11: 3-7 | H11: 5-5 | I11: 5-5 | J11: 2-8 | K11: 5-5 | L11: 6-4 | M11: 7-3
A12: Armaga B | B12: 4-6 | C12: 6-4 | D12: 6-4 | E12: 4-6 | F12: 5-5 | G12: 6-4 | H12: 6-4 | I12: 5-5 | J12: 6-4 | K12: 4-6 | L12: 5-5 | M12: 6-4
A13: Armaga D | B13: 5-5 | C13: 7-3 | D13: 8-2 | E13: 6-4 | F13: 6-4 | G13: 7-3 | H13: 4-6 | I13: 4-6 | J13: 3-7 | K13: 3-7 | L13: 4-6 | M13: 5-5
C17: Expected MU when they fight only with basic attk
L20: d
A21: most ideal strat
A22: eh strat
A23: worst strat
